{
 "cells": [
  {
   "cell_type": "code",
   "execution_count": 1,
   "id": "3826e446",
   "metadata": {},
   "outputs": [],
   "source": [
    "from keras.models import load_model\n",
    "import librosa\n",
    "import librosa.display\n",
    "import numpy as np"
   ]
  },
  {
   "cell_type": "code",
   "execution_count": 2,
   "id": "54008e64",
   "metadata": {},
   "outputs": [],
   "source": [
    "# 載入模型\n",
    "model = load_model('ScreamDemo1.h5')"
   ]
  },
  {
   "cell_type": "code",
   "execution_count": 3,
   "id": "9db6c1e7",
   "metadata": {},
   "outputs": [],
   "source": [
    "def load_data(path):\n",
    "    y1, sr1 = librosa.load(path, duration=2.97)  \n",
    "    ps = librosa.feature.melspectrogram(y=y1, sr=sr1)\n",
    "    lable = 0\n",
    "    return ps, lable"
   ]
  },
  {
   "cell_type": "code",
   "execution_count": 5,
   "id": "e6d8818d",
   "metadata": {},
   "outputs": [
    {
     "name": "stdout",
     "output_type": "stream",
     "text": [
      "[[1.2036945e-12 1.3678951e-02 2.5261229e-01 ... 9.2226905e-01\n",
      "  8.4149116e-01 9.4125360e-01]\n",
      " [4.4802139e-12 9.4088642e-03 4.3979436e-01 ... 8.8126481e-01\n",
      "  9.1394120e-01 2.0120904e+00]\n",
      " [9.4201730e-12 2.9758196e-03 6.3147998e-01 ... 3.8262048e+00\n",
      "  2.6232431e+00 3.1731474e+00]\n",
      " ...\n",
      " [4.9321172e-12 2.9209481e-05 3.0890061e-03 ... 4.4457004e-03\n",
      "  1.1183625e-02 1.2747736e-02]\n",
      " [2.7247850e-12 1.0239293e-05 8.3027733e-04 ... 1.7962893e-03\n",
      "  1.7129021e-03 3.6973022e-03]\n",
      " [2.1985845e-13 1.0191203e-06 1.2782632e-04 ... 9.2825445e-05\n",
      "  2.4553342e-04 1.8443126e-03]]\n",
      "<class 'numpy.ndarray'>\n",
      "(128, 128)\n",
      "WARNING:tensorflow:Model was constructed with shape (None, 128, 128, 1) for input KerasTensor(type_spec=TensorSpec(shape=(None, 128, 128, 1), dtype=tf.float32, name='conv2d_input'), name='conv2d_input', description=\"created by layer 'conv2d_input'\"), but it was called on an input with incompatible shape (32, 128).\n"
     ]
    },
    {
     "ename": "ValueError",
     "evalue": "in user code:\n\n    File \"C:\\Users\\USER\\anaconda3\\envs\\tensorflow\\lib\\site-packages\\keras\\engine\\training.py\", line 1801, in predict_function  *\n        return step_function(self, iterator)\n    File \"C:\\Users\\USER\\anaconda3\\envs\\tensorflow\\lib\\site-packages\\keras\\engine\\training.py\", line 1790, in step_function  **\n        outputs = model.distribute_strategy.run(run_step, args=(data,))\n    File \"C:\\Users\\USER\\anaconda3\\envs\\tensorflow\\lib\\site-packages\\keras\\engine\\training.py\", line 1783, in run_step  **\n        outputs = model.predict_step(data)\n    File \"C:\\Users\\USER\\anaconda3\\envs\\tensorflow\\lib\\site-packages\\keras\\engine\\training.py\", line 1751, in predict_step\n        return self(x, training=False)\n    File \"C:\\Users\\USER\\anaconda3\\envs\\tensorflow\\lib\\site-packages\\keras\\utils\\traceback_utils.py\", line 67, in error_handler\n        raise e.with_traceback(filtered_tb) from None\n    File \"C:\\Users\\USER\\anaconda3\\envs\\tensorflow\\lib\\site-packages\\keras\\engine\\input_spec.py\", line 228, in assert_input_compatibility\n        raise ValueError(f'Input {input_index} of layer \"{layer_name}\" '\n\n    ValueError: Exception encountered when calling layer \"sequential\" (type Sequential).\n    \n    Input 0 of layer \"conv2d\" is incompatible with the layer: expected min_ndim=4, found ndim=2. Full shape received: (32, 128)\n    \n    Call arguments received:\n      • inputs=tf.Tensor(shape=(32, 128), dtype=float32)\n      • training=False\n      • mask=None\n",
     "output_type": "error",
     "traceback": [
      "\u001b[1;31m---------------------------------------------------------------------------\u001b[0m",
      "\u001b[1;31mValueError\u001b[0m                                Traceback (most recent call last)",
      "Input \u001b[1;32mIn [5]\u001b[0m, in \u001b[0;36m<cell line: 9>\u001b[1;34m()\u001b[0m\n\u001b[0;32m      5\u001b[0m \u001b[38;5;28mprint\u001b[39m(\u001b[38;5;28mtype\u001b[39m(data))\n\u001b[0;32m      6\u001b[0m \u001b[38;5;28mprint\u001b[39m(data\u001b[38;5;241m.\u001b[39mshape)\n\u001b[1;32m----> 9\u001b[0m prediction \u001b[38;5;241m=\u001b[39m np\u001b[38;5;241m.\u001b[39margmax(\u001b[43mmodel\u001b[49m\u001b[38;5;241;43m.\u001b[39;49m\u001b[43mpredict\u001b[49m\u001b[43m(\u001b[49m\u001b[43mdata\u001b[49m\u001b[43m)\u001b[49m, axis\u001b[38;5;241m=\u001b[39m\u001b[38;5;241m-\u001b[39m\u001b[38;5;241m1\u001b[39m)\n\u001b[0;32m     10\u001b[0m \u001b[38;5;28mprint\u001b[39m(prediction)\n\u001b[0;32m     11\u001b[0m \u001b[38;5;28mprint\u001b[39m(\u001b[38;5;28mtype\u001b[39m(prediction))\n",
      "File \u001b[1;32m~\\anaconda3\\envs\\tensorflow\\lib\\site-packages\\keras\\utils\\traceback_utils.py:67\u001b[0m, in \u001b[0;36mfilter_traceback.<locals>.error_handler\u001b[1;34m(*args, **kwargs)\u001b[0m\n\u001b[0;32m     65\u001b[0m \u001b[38;5;28;01mexcept\u001b[39;00m \u001b[38;5;167;01mException\u001b[39;00m \u001b[38;5;28;01mas\u001b[39;00m e:  \u001b[38;5;66;03m# pylint: disable=broad-except\u001b[39;00m\n\u001b[0;32m     66\u001b[0m   filtered_tb \u001b[38;5;241m=\u001b[39m _process_traceback_frames(e\u001b[38;5;241m.\u001b[39m__traceback__)\n\u001b[1;32m---> 67\u001b[0m   \u001b[38;5;28;01mraise\u001b[39;00m e\u001b[38;5;241m.\u001b[39mwith_traceback(filtered_tb) \u001b[38;5;28;01mfrom\u001b[39;00m \u001b[38;5;28mNone\u001b[39m\n\u001b[0;32m     68\u001b[0m \u001b[38;5;28;01mfinally\u001b[39;00m:\n\u001b[0;32m     69\u001b[0m   \u001b[38;5;28;01mdel\u001b[39;00m filtered_tb\n",
      "File \u001b[1;32m~\\anaconda3\\envs\\tensorflow\\lib\\site-packages\\tensorflow\\python\\framework\\func_graph.py:1147\u001b[0m, in \u001b[0;36mfunc_graph_from_py_func.<locals>.autograph_handler\u001b[1;34m(*args, **kwargs)\u001b[0m\n\u001b[0;32m   1145\u001b[0m \u001b[38;5;28;01mexcept\u001b[39;00m \u001b[38;5;167;01mException\u001b[39;00m \u001b[38;5;28;01mas\u001b[39;00m e:  \u001b[38;5;66;03m# pylint:disable=broad-except\u001b[39;00m\n\u001b[0;32m   1146\u001b[0m   \u001b[38;5;28;01mif\u001b[39;00m \u001b[38;5;28mhasattr\u001b[39m(e, \u001b[38;5;124m\"\u001b[39m\u001b[38;5;124mag_error_metadata\u001b[39m\u001b[38;5;124m\"\u001b[39m):\n\u001b[1;32m-> 1147\u001b[0m     \u001b[38;5;28;01mraise\u001b[39;00m e\u001b[38;5;241m.\u001b[39mag_error_metadata\u001b[38;5;241m.\u001b[39mto_exception(e)\n\u001b[0;32m   1148\u001b[0m   \u001b[38;5;28;01melse\u001b[39;00m:\n\u001b[0;32m   1149\u001b[0m     \u001b[38;5;28;01mraise\u001b[39;00m\n",
      "\u001b[1;31mValueError\u001b[0m: in user code:\n\n    File \"C:\\Users\\USER\\anaconda3\\envs\\tensorflow\\lib\\site-packages\\keras\\engine\\training.py\", line 1801, in predict_function  *\n        return step_function(self, iterator)\n    File \"C:\\Users\\USER\\anaconda3\\envs\\tensorflow\\lib\\site-packages\\keras\\engine\\training.py\", line 1790, in step_function  **\n        outputs = model.distribute_strategy.run(run_step, args=(data,))\n    File \"C:\\Users\\USER\\anaconda3\\envs\\tensorflow\\lib\\site-packages\\keras\\engine\\training.py\", line 1783, in run_step  **\n        outputs = model.predict_step(data)\n    File \"C:\\Users\\USER\\anaconda3\\envs\\tensorflow\\lib\\site-packages\\keras\\engine\\training.py\", line 1751, in predict_step\n        return self(x, training=False)\n    File \"C:\\Users\\USER\\anaconda3\\envs\\tensorflow\\lib\\site-packages\\keras\\utils\\traceback_utils.py\", line 67, in error_handler\n        raise e.with_traceback(filtered_tb) from None\n    File \"C:\\Users\\USER\\anaconda3\\envs\\tensorflow\\lib\\site-packages\\keras\\engine\\input_spec.py\", line 228, in assert_input_compatibility\n        raise ValueError(f'Input {input_index} of layer \"{layer_name}\" '\n\n    ValueError: Exception encountered when calling layer \"sequential\" (type Sequential).\n    \n    Input 0 of layer \"conv2d\" is incompatible with the layer: expected min_ndim=4, found ndim=2. Full shape received: (32, 128)\n    \n    Call arguments received:\n      • inputs=tf.Tensor(shape=(32, 128), dtype=float32)\n      • training=False\n      • mask=None\n"
     ]
    }
   ],
   "source": [
    "path = \"audio/fold1/yisell_sound_2007_12_18_15_29_067921.wav\"\n",
    "\n",
    "data, labels = load_data(path)\n",
    "print(data)\n",
    "print(type(data))\n",
    "print(data.shape)\n",
    "\n",
    "\n",
    "prediction = np.argmax(model.predict(data), axis=-1)\n",
    "print(prediction)\n",
    "print(type(prediction))"
   ]
  },
  {
   "cell_type": "code",
   "execution_count": null,
   "id": "aad6632d",
   "metadata": {},
   "outputs": [],
   "source": []
  }
 ],
 "metadata": {
  "kernelspec": {
   "display_name": "Python 3 (ipykernel)",
   "language": "python",
   "name": "python3"
  },
  "language_info": {
   "codemirror_mode": {
    "name": "ipython",
    "version": 3
   },
   "file_extension": ".py",
   "mimetype": "text/x-python",
   "name": "python",
   "nbconvert_exporter": "python",
   "pygments_lexer": "ipython3",
   "version": "3.9.7"
  }
 },
 "nbformat": 4,
 "nbformat_minor": 5
}
